{"uuid": "c2a90d5c-e1ab-4241-ba9a-358743a97a59", "children": ["6916badd-ce0f-4f60-b64a-6efd3aae63a9"], "befores": [{"name": "handler", "status": "broken", "statusDetails": {"message": "selenium.common.exceptions.WebDriverException: Message: An unknown server-side error occurred while processing the command. Original error: Could not find a connected Android device in 24738ms.\n\n", "trace": "  File \"C:\\Python3\\lib\\site-packages\\pluggy\\callers.py\", line 187, in _multicall\n    res = hook_impl.function(*args)\n  File \"C:\\Python3\\lib\\site-packages\\_pytest\\fixtures.py\", line 1126, in pytest_fixture_setup\n    result = call_fixture_func(fixturefunc, request, kwargs)\n  File \"C:\\Python3\\lib\\site-packages\\_pytest\\fixtures.py\", line 925, in call_fixture_func\n    fixture_result = next(generator)\n  File \"F:\\ruanjianceshi\\diaoyuren_app_AutoTest\\cases\\conftest.py\", line 21, in handler\n    driver = webdriver.Remote(\"http://localhost:4723/wd/hub\", caps)\n  File \"C:\\Python3\\lib\\site-packages\\appium\\webdriver\\webdriver.py\", line 155, in __init__\n    proxy\n  File \"C:\\Python3\\lib\\site-packages\\selenium\\webdriver\\remote\\webdriver.py\", line 157, in __init__\n    self.start_session(capabilities, browser_profile)\n  File \"C:\\Python3\\lib\\site-packages\\appium\\webdriver\\webdriver.py\", line 225, in start_session\n    response = self.execute(RemoteCommand.NEW_SESSION, parameters)\n  File \"C:\\Python3\\lib\\site-packages\\selenium\\webdriver\\remote\\webdriver.py\", line 321, in execute\n    self.error_handler.check_response(response)\n  File \"C:\\Python3\\lib\\site-packages\\selenium\\webdriver\\remote\\errorhandler.py\", line 242, in check_response\n    raise exception_class(message, screen, stacktrace)\n"}, "start": 1615102070896, "stop": 1615102124079}], "start": 1615102070896, "stop": 1615102124886}