{"uuid": "0c66ed31-3bd3-4c69-86c4-357ce38cc4aa", "children": ["6679a0e8-0169-4ccd-88a6-f12285d05e89"], "befores": [{"name": "handler", "status": "broken", "statusDetails": {"message": "urllib3.exceptions.MaxRetryError: HTTPConnectionPool(host='localhost', port=4723): Max retries exceeded with url: /wd/hub/session (Caused by NewConnectionError('<urllib3.connection.HTTPConnection object at 0x000001AFB73730F0>: Failed to establish a new connection: [WinError 10061] 由于目标计算机积极拒绝，无法连接。',))\n", "trace": "  File \"C:\\Python3\\lib\\site-packages\\pluggy\\callers.py\", line 187, in _multicall\n    res = hook_impl.function(*args)\n  File \"C:\\Python3\\lib\\site-packages\\_pytest\\fixtures.py\", line 1126, in pytest_fixture_setup\n    result = call_fixture_func(fixturefunc, request, kwargs)\n  File \"C:\\Python3\\lib\\site-packages\\_pytest\\fixtures.py\", line 925, in call_fixture_func\n    fixture_result = next(generator)\n  File \"F:\\ruanjianceshi\\diaoyuren_app_AutoTest\\cases\\conftest.py\", line 21, in handler\n    driver = webdriver.Remote(\"http://localhost:4723/wd/hub\", caps)\n  File \"C:\\Python3\\lib\\site-packages\\appium\\webdriver\\webdriver.py\", line 155, in __init__\n    proxy\n  File \"C:\\Python3\\lib\\site-packages\\selenium\\webdriver\\remote\\webdriver.py\", line 157, in __init__\n    self.start_session(capabilities, browser_profile)\n  File \"C:\\Python3\\lib\\site-packages\\appium\\webdriver\\webdriver.py\", line 225, in start_session\n    response = self.execute(RemoteCommand.NEW_SESSION, parameters)\n  File \"C:\\Python3\\lib\\site-packages\\selenium\\webdriver\\remote\\webdriver.py\", line 319, in execute\n    response = self.command_executor.execute(driver_command, params)\n  File \"C:\\Python3\\lib\\site-packages\\selenium\\webdriver\\remote\\remote_connection.py\", line 374, in execute\n    return self._request(command_info[0], url, body=data)\n  File \"C:\\Python3\\lib\\site-packages\\selenium\\webdriver\\remote\\remote_connection.py\", line 397, in _request\n    resp = self._conn.request(method, url, body=body, headers=headers)\n  File \"C:\\Python3\\lib\\site-packages\\urllib3\\request.py\", line 79, in request\n    method, url, fields=fields, headers=headers, **urlopen_kw\n  File \"C:\\Python3\\lib\\site-packages\\urllib3\\request.py\", line 170, in request_encode_body\n    return self.urlopen(method, url, **extra_kw)\n  File \"C:\\Python3\\lib\\site-packages\\urllib3\\poolmanager.py\", line 375, in urlopen\n    response = conn.urlopen(method, u.request_uri, **kw)\n  File \"C:\\Python3\\lib\\site-packages\\urllib3\\connectionpool.py\", line 796, in urlopen\n    **response_kw\n  File \"C:\\Python3\\lib\\site-packages\\urllib3\\connectionpool.py\", line 796, in urlopen\n    **response_kw\n  File \"C:\\Python3\\lib\\site-packages\\urllib3\\connectionpool.py\", line 796, in urlopen\n    **response_kw\n  File \"C:\\Python3\\lib\\site-packages\\urllib3\\connectionpool.py\", line 756, in urlopen\n    method, url, error=e, _pool=self, _stacktrace=sys.exc_info()[2]\n  File \"C:\\Python3\\lib\\site-packages\\urllib3\\util\\retry.py\", line 573, in increment\n    raise MaxRetryError(_pool, url, error or ResponseError(cause))\n"}, "start": 1615098912006, "stop": 1615098931652}], "start": 1615098912006, "stop": 1615098934474}