INFO     selenium.webdriver.remote.remote_connection:remote_connection.py:117 Could not connect to port 4723 on host localhost
INFO     selenium.webdriver.remote.remote_connection:remote_connection.py:136 Could not get IP address for host: localhost
DEBUG    selenium.webdriver.remote.remote_connection:remote_connection.py:388 POST http://localhost:4723/wd/hub/session {"capabilities": {"firstMatch": [{"platformName": "Android", "appium:platformVersion": "5", "appium:deviceName": "127.0.0.1:21503", "appium:appPackage": "com.lchr.diaoyu", "appium:appActivity": "com.lchr.diaoyu.SplashActivity", "appium:noReset": true, "appium:newCommandTimeout": 6000, "appium:skipServerInstallation": true, "appium:automationName": "UiAutomator2", "appium:ensureWebviewsHavePages": true}]}, "desiredCapabilities": {"platformName": "Android", "platformVersion": "5", "deviceName": "127.0.0.1:21503", "appPackage": "com.lchr.diaoyu", "appActivity": "com.lchr.diaoyu.SplashActivity", "noReset": true, "newCommandTimeout": 6000, "skipServerInstallation": true, "automationName": "UiAutomator2", "ensureWebviewsHavePages": true}}
DEBUG    urllib3.connectionpool:connectionpool.py:231 Starting new HTTP connection (1): localhost:4723
DEBUG    urllib3.util.retry:retry.py:575 Incremented Retry for (url='/wd/hub/session'): Retry(total=2, connect=None, read=None, redirect=None, status=None)
WARNING  urllib3.connectionpool:connectionpool.py:781 Retrying (Retry(total=2, connect=None, read=None, redirect=None, status=None)) after connection broken by 'NewConnectionError('<urllib3.connection.HTTPConnection object at 0x000001AFB73599B0>: Failed to establish a new connection: [WinError 10061] 由于目标计算机积极拒绝，无法连接。',)': /wd/hub/session
DEBUG    urllib3.connectionpool:connectionpool.py:231 Starting new HTTP connection (2): localhost:4723
DEBUG    urllib3.util.retry:retry.py:575 Incremented Retry for (url='/wd/hub/session'): Retry(total=1, connect=None, read=None, redirect=None, status=None)
WARNING  urllib3.connectionpool:connectionpool.py:781 Retrying (Retry(total=1, connect=None, read=None, redirect=None, status=None)) after connection broken by 'NewConnectionError('<urllib3.connection.HTTPConnection object at 0x000001AFB7359C88>: Failed to establish a new connection: [WinError 10061] 由于目标计算机积极拒绝，无法连接。',)': /wd/hub/session
DEBUG    urllib3.connectionpool:connectionpool.py:231 Starting new HTTP connection (3): localhost:4723
DEBUG    urllib3.util.retry:retry.py:575 Incremented Retry for (url='/wd/hub/session'): Retry(total=0, connect=None, read=None, redirect=None, status=None)
WARNING  urllib3.connectionpool:connectionpool.py:781 Retrying (Retry(total=0, connect=None, read=None, redirect=None, status=None)) after connection broken by 'NewConnectionError('<urllib3.connection.HTTPConnection object at 0x000001AFB7359E80>: Failed to establish a new connection: [WinError 10061] 由于目标计算机积极拒绝，无法连接。',)': /wd/hub/session
DEBUG    urllib3.connectionpool:connectionpool.py:231 Starting new HTTP connection (4): localhost:4723